Workbook
Name FLAPAQ: FLAPAQ!$B$1:$I$28
Name FLATCQ: FLATCQ!$B$1:$I$30
Name ICQ: ICQ!$B$1:$J$82
Name PAQ: PAQ!$B$1:$I$102
Name SCQ: SCQ!$B$1:$I$135
Name STQ: STQ!$B$1:$H$13
Name STQ: #REF!
Name TCQ: TCQ!$B$1:$J$160

Sheet TOC
A1: Table number | B1: Table Title
A2: Table 22.A.1 | B2: List of all trend scales
A3: Table 22.A.2 | B3: OECD mean and standard deviation of the original WLEs for the new scales
A4: Table 22.A.3 | B4: OECD mean and standard deviation of the original WLEs in PISA 2022 for trend scales linked to PISA 2025
A5: Table 22.A.4 | B5: OECD mean and standard deviation of the original WLEs in PISA 2018 for trend scales linked to PISA 2025
A6: Table 22.A.5 | B6: OECD mean and standard deviation of the original WLEs in PISA 2012 for trend scales linked to PISA 2025
A7: Table 22.A.6 | B7: Scaling constants used as linear transformations for original WLEs in PISA 2025 to link trend scales to PISA 2015 (and PISA 2006)
A8: Table 22.A.7 | B8: Variables derived from the Student Questionnaire
A9: Table 22.A.8 | B9: Mapping of ISCED levels to years of education
A10: Table 22.A.9 | B10: ISCEDP values and labels
A11: Table 22.A.10 | B11: Creation of EXPECEDU index
A12: Table 22.A.11 | B12: Cronbach's alpha for the IRT scales in the Student Questionnaire
... A159: Table 22.A.158 | B159: Questionnaire Trend Items Parameters

Sheet T22.A.1
A1: Table of Contents
A3: Table 22.A.1
A4: List of all trend scales
A6: Scale | B6: PISA cycle linked to
A7: Student Questionnaire
A8: BELONG | B8: 2018
A9: BULLIED | B9: 2018
A10: DISCLISCI | B10: 2015
A11: ENVAWARE | B11: 2015
A12: FAMSUP | B12: 2022
A13: FEELSAFE | B13: 2022
A14: ICTRES | B14: 2022
A15: JOYSCIE | B15: 2015
A16: TEACHSUP | B16: 2015
A17: ICT Familiarity Questionnaire
A18: ICTFEED | B18: 2022
A19: ICTHOME | B19: 2022
A20: ICTINFO | B20: 2022
A21: ICTOUT | B21: 2022
A22: ICTQUAL | B22: 2022
A23: ICTREG | B23: 2022
A24: ICTSCH | B24: 2022
A25: ICTWKDY | B25: 2022
A26: ICTWKEND | B26: 2022
A27: INTICT | B27: 2018
A28: SOIAICT | B28: 2018
A29: Parent Questionnaire
A30: PARINVOL | B30: 2022
A31: PQENPERC | B31: 2015
A32: PQENVOPT | B32: 2015
A33: PQSCHOOL | B33: 2018
A34: PRESUPP | B34: 2015
A35: School Questionnaire
A36: ALLACTIV | B36: 2022
A37: DIGPREP | B37: 2022
A38: EDULEAD | B38: 2022
A39: EDUSHORT | B39: 2018
A40: ENCOURPG | B40: 2022
A41: NEGSCLIM | B41: 2022
A42: STAFFSHORT | B42: 2018
...

Sheet T22.A.2
A1: Table of Contents
A3: Table 22.A.2
A4: OECD mean and standard deviation of the original WLEs for the new scales
A6: Scale | B6: Mean | C6: SD
A7: Student Questionnaire
A8: AIUSESCH | B8: -0.57621661 | C8: 1.0198009
A9: COGABIL | B9: -0.16576047 | C9: 1.0327374
A10: COGACSC | B10: -0.54321822 | C10: 1.086203
A11: COLLENEFF | B11: -0.46386699 | C11: 1.0126689
A12: CURIO | B12: -0.2090514 | C12: 1.0162815
A13: EFFSCIE | B13: -0.59277614 | C13: 1.0895968
A14: ENGSCIPR | B14: -0.62427062 | C14: 1.0177516
A15: ENPROBS | B15: -0.43729898 | C15: 1.0803779
A16: ENVAPART | B16: -0.19730456 | C16: 1.0049689
A17: ENVCAPCH | B17: -0.41983963 | C17: 1.058524
A18: GOALSET | B18: -0.64933933 | C18: 1.1125233
A19: HOMEPOS | B19: -0.56644531 | C19: 1.1537855
... A24: STBELSCIE | B24: -0.079620913 | C24: 1.0324338
A25: ICT Familiarity Questionnaire
A26: DIGINTLRN | B26: -0.60437746 | C26: 1.0295523
A27: Parent Questionnaire
A28: FGENSUP | B28: -0.40502659 | C28: 1.067452
A29: FSCISUP | B29: -0.15555926 | C29: 1.1877363
A30: PQDIGEFF | B30: 0.20802681 | C30: 1.0259694
A31: PQFEED | B31: 0.23601993 | C31: 0.95055688
A32: PQSCAR | B32: 0.22609362 | C32: 0.42259882
A33: PQSELFREG | B33: 0.08842541 | C33: 1.1637742
A34: PVDRSCUSE | B34: 0.53333929 | C34: 1.1615782
A35: School Questionnaire
A36: AVLRSOFT | B36: 0.7893071 | C36: 1.1470767
A37: DELGLOB | B37: -0.2406465 | C37: 0.5640617
A38: FREESCIE | B38: -0.6404217 | C38: 0.8308175
A39: OPPACTENV | B39: -0.3997431 | C39: 1.1872367
A40: PISASUPP | B40: -1.1777151 | C40: 0.5857358
A41: PRIORLRN | B41: -0.3607814 | C41: 0.9549675
A42: SCTRAIN | B42: 0.1276624 | C42: 0.5655941
A43: SESASSESS | B43: -0.6202871 | C43: 1.1498933
A44: Teacher Questionnaire
A45: BELLRNG | B45: -0.31563034 | C45: 1.0139353
A46: CONEXSCI | B46: -0.6462144 | C46: 0.76224439
...

Sheet T22.A.3
A1: Table of Contents
A3: Table 22.A.3
A4: OECD mean and standard deviation of the original WLEs in PISA 2022 for trend scales linked to PISA 2025
A6: Scale | B6: Mean | C6: SD
A7: Student Questionnaire
A8: FAMSUP | B8: 0.5744 | C8: 0.9633
A9: FEELSAFE | B9: 1.7689 | C9: 1.645
A10: ICTRES | B10: 0.33671174 | C10: 0.69810361
A11: Parent Questionnaire
A12: PARINVOL | B12: -0.55308483 | C12: 1.0552016
A13: ICT familiarity questionnaire
A14: ICTSCH | B14: 1.4221616 | C14: 0.57047698
A15: ICTHOME | B15: 1.6034869 | C15: 0.51748369
A16: ICTQUAL | B16: 0.26738857 | C16: 1.2336738
A17: ICTFEED | B17: -0.48302712 | C17: 1.0211427
A18: ICTOUT | B18: 0.16785814 | C18: 0.98993467
A19: ICTWKDY | B19: -0.44397948 | C19: 0.61537695
A20: ICTWKEND | B20: -0.67647149 | C20: 0.8234518
A21: ICTREG | B21: -0.83335098 | C21: 1.3871951
A22: ICTINFO | B22: -0.018925248 | C22: 1.0634728
A23: School Questionnaire
A24: ALLACTIV | B24: 0.020045385 | C24: 0.91355227
A25: DIGPREP | B25: 0.14546351 | C25: 1.0092317
A26: EDULEAD | B26: 0.080588237 | C26: 0.94133877
A27: ENCOURPG | B27: -0.3671992 | C27: 1.080592
A28: NEGSCLIM | B28: -1.2709127 | C28: 1.2873045
A29: STDTEST | B29: -0.066804516 | C29: 1.144841
A30: TDTEST | B30: 0.27795455 | C30: 0.97491057
A31: Teacher Questionnaire
A32: EXCHT | B32: 0.32001569 | C32: 0.624387
A33: SEFFCM | B33: 1.55319 | C33: 1.4793824
A34: SEFFINS | B34: 1.4494492 | C34: 1.1312022
A35: SEFFREL | B35: 1.4315132 | C35: 1.4677541

Sheet T22.A.4
A1: Table of Contents
A3: Table 22.A.4
A4: OECD mean and standard deviation of the original WLEs in PISA 2018 for trend scales linked to PISA 2025
A6: Scale | B6: Mean | C6: SD
A7: Student Questionnaire
A8: BELONG | B8: 0.76821115 | C8: 1.1367603
A9: BULLIED (BEINGBULLIED in 2018) | B9: -1.2167995 | C9: 0.76362448
A10: ICT Familiarity Questionnaire
A11: INTICT | B11: 0.63285188 | C11: 1.1054315
A12: SOIAICT | B12: 0.060049244 | C12: 1.3505611
A13: Parent Questionnaire
A14: PQSCHOOL | B14: 1.2325982 | C14: 1.3693617
A15: School Questionnaire
A16: EDUSHORT | B16: -0.7828264 | C16: 1.1122459
A17: STAFFSHORT | B17: -0.86835407 | C17: 0.82658883
A18: Teacher Questionnaire
A19: EXCHT | B19: 0.32001569 | C19: 0.624387
A20: SEFFCM | B20: 1.55319 | C20: 1.4793824
A21: SEFFINS | B21: 1.4494492 | C21: 1.1312022
A22: SEFFREL | B22: 1.4315132 | C22: 1.4677541

Sheet T22.A.5
A1: Table of Contents
A3: Table 22.A.5
A4: OECD mean and standard deviation of the original WLEs in PISA 2012 for trend scales linked to PISA 2025
A6: Scale | B6: Mean | C6: SD
A7: Student Questionnaire
A8: DISCLISCI | B8: 0.53 | C8: 1.3
A9: TEACHSUP | B9: 0.75 | C9: 1.24
A10: Parent Questionnaire
A11: PRESUPP | B11: -0.69 | C11: 0.68
A12: Teacher Questionnaire
A13: SETEACH | B13: 1.41 | C13: 1.14

Sheet T22.A.6
A1: Table of Contents
A3: Table 22.A.6
A4: Scaling constants used as linear transformations for original WLEs in PISA 2025 to link trend scales to PISA 2015 (and PISA 2006)
A6: Scale | B6: A | C6: B
A7: Student Questionnaire
A8: ENVAWARE | B8: 0.58 | C8: -0.12
A9: JOYSCIE | B9: 1.05 | C9: -0.52
A10: Parent Questionnaire
A11: PQGENSCI | B11: 0.77 | C11: -1.11
A12: PQENPERC | B12: 1.64 | C12: -2.34
A13: PQENVOPT | B13: 1.11 | C13: 1

Sheet T22.A.7
A1: Table of Contents
A3: Table 22.A.7
A4: Variables derived from the Student Questionnaire
A6: DV name | B6: DV label
A7: Simple DVs
A8: AGE | B8: Students' age
A9: GRADE | B9: Grade compared to modal grade
A10: ST004D01 | B10: Students' gender
A11: MALE | B11: Students' male gender
A12: P1ISCED | B12: Parent/guardian 1's level of education
A13: P2ISCED | B13: Parent/guardian 2's level of education
A14: HISCED | B14: Highest educational level of parents/guardians
A15: PAREDINT | B15: Highest education of parents in years
A16: OCOP1 | B16: Parent 1 occupational code
A17: OCOP2 | B17: Parent 2 occupational code
A18: BP1MJ | B18: Parent/guardian 1's occupational status
A19: BP2MJ | B19: Parent/guardian 2's occupational status
... A35: EXERPRAC | B35: Excersice or practise sport before or after school
A36: IRT scales
A37: HOMEPOS | B37: Home possessions
A38: ICTRES | B38: ICT resources
A39: BELONG | B39: Students' sense of belonging
A40: BULLIED | B40: Student reports on being bullied
A41: FEELSAFE | B41: Student reports on feeling safe
A42: DISCLISCI | B42: Disciplinary climate in school science
A43: TEACHSUP | B43: Teacher support in science classes
A44: COGACSC | B44: Cognitive activation in science classes
A45: SCIECOLLR | B45: Collaborative reasoning in science classes
A46: JOYSCIE | B46: Students' enjoyment of science
A47: EFFSCIE | B47: Science self-efficacy
A48: STBELSCIE | B48: Students' beliefs about the nature of science
... A62: AIUSESCH | B62: Students' AI use at school
A63: Complex composite index
A64: ESCS | B64: Index of economic, social and cultural status

Sheet T22.A.8
A1: Table of Contents
A3: Table 22.A.8
A4: Mapping of ISCED levels to years of education
A6: Index value for P1ISCED/P2ISCED | B6: ISCED level | C6: Median cumulative years of education
A7: 1 | B7: My parent does not have any of these qualifications | C7: 6
A8: 2 | B8: ISCED level 2 (Lower secondary education) | C8: 9
A9: 3 | B9: ISCED level 3.3 (Upper secondary education with no direct access to tertiary education) | C9: 12
A10: 4 | B10: ISCED level 3.4 (Upper secondary education of education with direct access to tertiary education) | C10: 12
A11: 5 | B11: ISCED level 4 (Post-secondary non-tertiary education) | C11: 12
A12: 6 | B12: ISCED level 5 (Short-cycle tertiary education) | C12: 14.5
A13: 7 | B13: ISCED level 6 (Bachelor’s or equivalent) | C13: 16
A14: 8 | B14: ISCED level 7 (Master's or equivalent) | C14: 16
A15: 9 | B15: ISCED level 8 (Doctoral or equivalent) | C15: 16

Sheet T22.A.9
A1: Table of Contents
A3: Table 22.A.9
A4: ISCEDP values and labels
A6: ISCEDP value | B6: ISCEDP label
A7: 244 | B7: Lower secondary general education: Sufficient for level completion with direct access to upper secondary education
A8: 254 | B8: Lower secondary vocational education: Sufficient for level completion with direct access to upper secondary education
A9: 344 | B9: Upper secondary general education: Sufficient for level completion with direct access to tertiary or post-secondary non-tertiary education
A10: 354 | B10: Upper secondary vocational education: Sufficient for level completion with direct access to tertiary or post-secondary non-tertiary education

Sheet T22.A.10
A1: Table of Contents
A3: Table 22.A.10
A4: Creation of EXPECEDU index
A6: Index value | B6: Value label | C6: Index creation rule
A7: 9 | B7: ISCED Level 8 | C7: Assign this score if “Yes” to item ST327Q08JA
A8: 8 | B8: ISCED level 7 | C8: Assign this score if “No” or “IDK” to item ST327Q08JA and “Yes” to item ST327Q07JA
A9: 7 | B9: ISCED Level 6 | C9: Assign this score if “No” or “IDK” to item ST327Q08JA and ST327Q07JA and “Yes” to item ST327Q06JA
A10: 6 | B10: ISCED Level 5 | C10: Assign this score if “No” or “IDK” to item ST327Q08JA and ST327Q07JA and ST327Q06JA and “Yes” to item ST327Q05JA
A11: 5 | B11: ISCED Level 4 | C11: Assign this score if “No” or “IDK” to item ST327Q08JA and ST327Q07JA and ST327Q06JA and ST327Q05JA and “Yes” to item ST327Q04JA
A12: 4 | B12: ISCED Level 3.4 | C12: Assign this score if “No” or “IDK” to item ST327Q08JA and ST327Q07JA and ST327Q06JA and ST327Q05JA and ST327Q04JA and “Yes” to item ST327Q03JA
A13: 3 | B13: ISCED Level 3.3 | C13: Assign this score if “No” or “IDK” to item ST327Q08JA and ST327Q07JA and ST327Q06JA and ST327Q05JA and ST327Q04JA and ST327Q03JA and “Yes” to item ST327Q02JA
A14: 2 | B14: ISCED Level 2 | C14: Assign this score if “No” or “IDK” to item ST327Q08JA and ST327Q07JA and ST327Q06JA and ST327Q05JA and ST327Q04JA and ST327Q03JA and ST327Q02JA and “Yes” to item ST327Q01JA
A15: 1 | B15: Less than ISCED Level 2 | C15: Assign this score if “No” to items 1-8 in this question and “No” or “I don't know” to item 1 in this question

Sheet T22.A.11
A1: Table of Contents
A3: Table 22.A.11
A4: Cronbach's alpha for the IRT scales in the Student Questionnaire
A6: Country/economy (language group) | B6: HOMEPOS | C6: ICTRES | D6: AIUSESCH | E6: BELONG | F6: BULLIED | G6: COGABIL | H6: COGACSC | I6: COLLENEFF | J6: CURIO | K6: DISCLISCI | L6: EFFSCIE | M6: ENGSCIPR | N6: ENPROBS | O6: ENVAPART | P6: ENVAWARE | Q6: ENVCAPCH | R6: FAMSUP | S6: FEELSAFE | T6: GOALSET | U6: JOYSCIE | V6: OPENVLRN | W6: PERSEV | X6: SCIECOLLR | Y6: SELFREG | Z6: TEACHSUP | AA6: STBELSCIE
A7: Albania - Albanian | B7: 0.78 | C7: 0.66 | D7: 0.89 | E7: 0.68 | F7: 0.82 | G7: 0.89 | H7: 0.87 | I7: 0.88 | J7: 0.69 | K7: 0.9 | L7: 0.88 | M7: 0.92 | N7: 0.83 | O7: 0.82 | P7: 0.92 | Q7: 0.87 | R7: 0.93 | S7: 0.86 | T7: 0.86 | U7: 0.92 | V7: 0.84 | W7: 0.54 | X7: 0.84 | Y7: 0.86 | Z7: 0.89 | AA7: 0.86 | AD7: sq-AL | AE7: =VLOOKUP(AD7,GroupLabels!$E$2:$H$145,3,0) -> Albania - Albanian
A8: Argentina - Spanish | B8: 0.79 | C8: 0.68 | D8: 0.87 | E8: 0.75 | F8: 0.76 | G8: 0.78 | H8: 0.8 | I8: 0.83 | J8: 0.77 | K8: 0.88 | L8: 0.84 | M8: 0.88 | N8: 0.78 | O8: 0.77 | P8: 0.86 | Q8: 0.82 | R8: 0.9 | S8: 0.81 | T8: 0.78 | U8: 0.9 | V8: 0.8 | W8: 0.71 | X8: 0.76 | Y8: 0.74 | Z8: 0.9 | AA8: 0.87 | AD8: es-AR | AE8: =VLOOKUP(AD8,GroupLabels!$E$2:$H$145,3,0) -> Argentina - Spanish
A9: Armenia - Armenian | B9: 0.71 | C9: 0.68 | D9: 0.87 | E9: 0.7 | F9: 0.83 | G9: 0.78 | H9: 0.88 | I9: 0.88 | J9: 0.73 | K9: 0.91 | L9: 0.87 | M9: 0.88 | N9: 0.78 | O9: 0.78 | P9: 0.9 | Q9: 0.88 | R9: 0.91 | S9: 0.92 | T9: 0.8 | U9: 0.92 | V9: 0.84 | W9: 0.64 | X9: 0.81 | Y9: 0.8 | Z9: 0.92 | AA9: 0.91 | AD9: hy-AM | AE9: =VLOOKUP(AD9,GroupLabels!$E$2:$H$145,3,0) -> Armenia - Armenian
A10: Australia - English | B10: 0.72 | C10: 0.55 | D10: 0.9 | E10: 0.82 | F10: 0.78 | G10: 0.87 | H10: 0.85 | I10: 0.89 | J10: 0.77 | K10: 0.91 | L10: 0.9 | M10: 0.86 | N10: 0.83 | O10: 0.79 | P10: 0.89 | Q10: 0.82 | R10: 0.87 | S10: 0.89 | T10: 0.85 | U10: 0.95 | V10: 0.83 | W10: 0.78 | X10: 0.79 | Y10: 0.76 | Z10: 0.93 | AA10: 0.86 | AD10: en-AU | AE10: =VLOOKUP(AD10,GroupLabels!$E$2:$H$145,3,0) -> Australia - English
A11: Austria - German | B11: 0.74 | C11: 0.57 | D11: 0.86 | E11: 0.76 | F11: 0.81 | G11: 0.8 | H11: 0.79 | I11: 0.85 | J11: 0.78 | K11: 0.87 | L11: 0.84 | M11: 0.89 | N11: 0.78 | O11: 0.74 | P11: 0.87 | Q11: 0.81 | R11: 0.87 | S11: 0.79 | T11: 0.74 | U11: 0.92 | V11: 0.81 | W11: 0.7 | X11: 0.81 | Y11: 0.7 | Z11: 0.89 | AA11: 0.87 | AD11: de-AT | AE11: =VLOOKUP(AD11,GroupLabels!$E$2:$H$145,3,0) -> Austria - German
A12: Azerbaijan - Azerbaijani | B12: 0.78 | C12: 0.71 | D12: 0.88 | E12: 0.72 | F12: 0.82 | G12: 0.86 | H12: 0.89 | I12: 0.88 | J12: 0.76 | K12: 0.91 | L12: 0.84 | M12: 0.9 | N12: 0.84 | O12: 0.79 | P12: 0.89 | Q12: 0.89 | R12: 0.91 | S12: 0.93 | T12: 0.83 | U12: 0.95 | V12: 0.88 | W12: 0.77 | X12: 0.89 | Y12: 0.82 | Z12: 0.89 | AA12: 0.92 | AD12: az-QZ | AE12: =VLOOKUP(AD12,GroupLabels!$E$2:$H$145,3,0) -> Azerbaijan - Azerbaijani
A13: Azerbaijan - Russian | B13: 0.78 | C13: 0.71 | D13: 0.88 | E13: 0.8 | F13: 0.84 | G13: 0.86 | H13: 0.91 | I13: 0.9 | J13: 0.73 | K13: 0.93 | L13: 0.87 | M13: 0.93 | N13: 0.8 | O13: 0.83 | P13: 0.92 | Q13: 0.87 | R13: 0.91 | S13: 0.89 | T13: 0.82 | U13: 0.92 | V13: 0.88 | W13: 0.7 | X13: 0.89 | Y13: 0.78 | Z13: 0.92 | AA13: 0.91 | AD13: ru-QZ | AE13: =VLOOKUP(AD13,GroupLabels!$E$2:$H$145,3,0) -> Azerbaijan - Russian
A14: Belgium (Flemish Community) - Dutch | B14: 0.71 | C14: 0.54 | D14: 0.83 | E14: 0.77 | F14: 0.73 | G14: 0.81 | H14: 0.8 | I14: 0.84 | J14: 0.79 | K14: 0.88 | L14: 0.86 | M14: 0.88 | N14: 0.81 | O14: 0.76 | P14: 0.88 | Q14: 0.79 | R14: 0.86 | S14: 0.9 | T14: 0.76 | U14: 0.96 | V14: 0.85 | W14: 0.77 | X14: 0.77 | Y14: 0.68 | Z14: 0.91 | AA14: 0.84 | AD14: nl-BE | AE14: =VLOOKUP(AD14,GroupLabels!$E$2:$H$145,3,0) -> Belgium (Flemish Community) - Dutch
A15: Belgium (French Community) - French | B15: 0.73 | C15: 0.54 | D15: 0.85 | E15: 0.74 | F15: 0.79 | G15: 0.76 | H15: 0.79 | I15: 0.82 | J15: 0.78 | K15: 0.87 | L15: 0.83 | M15: 0.88 | N15: 0.76 | O15: 0.74 | P15: 0.84 | Q15: 0.76 | R15: 0.8 | S15: 0.83 | T15: 0.76 | U15: 0.92 | V15: 0.84 | W15: 0.76 | X15: 0.76 | Y15: 0.71 | Z15: 0.89 | AA15: 0.82 | AD15: fr-BE | AE15: =VLOOKUP(AD15,GroupLabels!$E$2:$H$145,3,0) -> Belgium (French Community) - French
A16: Belgium (French Community) - German | B16: 0.69 | C16: 0.53 | D16: 0.86 | E16: 0.72 | F16: 0.79 | G16: 0.77 | H16: 0.8 | I16: 0.88 | J16: 0.79 | K16: 0.9 | L16: 0.87 | M16: 0.92 | N16: 0.78 | O16: 0.77 | P16: 0.89 | Q16: 0.82 | R16: 0.87 | S16: 0.79 | T16: 0.77 | U16: 0.95 | V16: 0.86 | W16: 0.68 | X16: 0.84 | Y16: 0.76 | Z16: 0.91 | AA16: 0.88 | AD16: de-BE | AE16: =VLOOKUP(AD16,GroupLabels!$E$2:$H$145,3,0) -> Belgium (French Community) - German
A17: Brazil - Portuguese | B17: 0.82 | C17: 0.7 | D17: 0.87 | E17: 0.76 | F17: 0.73 | G17: 0.83 | H17: 0.84 | I17: 0.84 | J17: 0.72 | K17: 0.86 | L17: 0.88 | M17: 0.92 | N17: 0.77 | O17: 0.79 | P17: 0.9 | Q17: 0.83 | R17: 0.91 | S17: 0.84 | T17: 0.83 | U17: 0.88 | V17: 0.8 | W17: 0.58 | X17: 0.83 | Y17: 0.76 | Z17: 0.9 | AA17: 0.88 | AD17: pt-BR | AE17: =VLOOKUP(AD17,GroupLabels!$E$2:$H$145,3,0) -> Brazil - Portuguese
A18: Brunei Darussalam - English | B18: 0.79 | C18: 0.65 | D18: 0.85 | E18: 0.72 | F18: 0.73 | G18: 0.79 | H18: 0.78 | I18: 0.79 | J18: 0.71 | K18: 0.79 | L18: 0.82 | M18: 0.85 | N18: 0.75 | O18: 0.69 | P18: 0.85 | Q18: 0.69 | R18: 0.86 | S18: 0.79 | T18: 0.75 | U18: 0.9 | V18: 0.74 | W18: 0.66 | X18: 0.73 | Y18: 0.72 | Z18: 0.85 | AA18: 0.78 | AD18: en-BN | AE18: =VLOOKUP(AD18,GroupLabels!$E$2:$H$145,3,0) -> Brunei Darussalam - English
... A20: Bulgaria - Bulgarian | B20: 0.76 | C20: 0.67 | D20: 0.88 | E20: 0.71 | F20: 0.85 | G20: 0.84 | H20: 0.87 | I20: 0.84 | J20: 0.76 | K20: 0.91 | L20: 0.88 | M20: 0.91 | N20: 0.82 | O20: 0.84 | P20: 0.91 | Q20: 0.84 | R20: 0.9 | S20: 0.88 | T20: 0.78 | U20: 0.89 | V20: 0.83 | W20: 0.73 | X20: 0.84 | Y20: 0.76 | Z20: 0.91 | AA20: 0.89 | AD20: bg-BG | AE20: =VLOOKUP(AD20,GroupLabels!$E$2:$H$145,3,0) -> Bulgaria - Bulgarian
A21: Cambodia - Khmer | B21: 0.84 | C21: 0.66 | D21: a | E21: 0.58 | F21: 0.69 | G21: a | H21: 0.79 | I21: 0.59 | J21: 0.52 | K21: a | L21: 0.78 | M21: 0.82 | N21: a | O21: 0.64 | P21: 0.81 | Q21: 0.56 | R21: 0.85 | S21: 0.79 | T21: a | U21: 0.8 | V21: 0.53 | W21: 0.56 | X21: 0.76 | Y21: a | Z21: a | AA21: 0.61 | AD21: km-KH | AE21: =VLOOKUP(AD21,GroupLabels!$E$2:$H$145,3,0) -> Cambodia - Khmer
A22: Canada - English | B22: 0.77 | C22: 0.6 | D22: 0.91 | E22: 0.81 | F22: 0.81 | G22: 0.88 | H22: 0.82 | I22: 0.9 | J22: 0.76 | K22: 0.89 | L22: 0.88 | M22: 0.89 | N22: 0.84 | O22: 0.81 | P22: 0.9 | Q22: 0.84 | R22: 0.87 | S22: 0.89 | T22: 0.87 | U22: 0.95 | V22: 0.8 | W22: 0.78 | X22: 0.78 | Y22: 0.8 | Z22: a | AA22: 0.91 | AD22: en-CA | AE22: =VLOOKUP(AD22,GroupLabels!$E$2:$H$145,3,0) -> Canada - English
A23: Canada - French | B23: 0.74 | C23: 0.55 | D23: 0.87 | E23: 0.79 | F23: 0.81 | G23: 0.81 | H23: 0.82 | I23: 0.86 | J23: 0.79 | K23: 0.87 | L23: 0.86 | M23: 0.91 | N23: 0.8 | O23: 0.76 | P23: 0.88 | Q23: 0.8 | R23: 0.83 | S23: 0.89 | T23: 0.84 | U23: 0.91 | V23: 0.83 | W23: 0.77 | X23: 0.72 | Y23: 0.74 | Z23: a | AA23: 0.86 | AD23: fr-CA | AE23: =VLOOKUP(AD23,GroupLabels!$E$2:$H$145,3,0) -> Canada - French
A24: Chile - Spanish | B24: 0.82 | C24: 0.69 | D24: 0.86 | E24: 0.77 | F24: 0.79 | G24: 0.86 | H24: 0.88 | I24: 0.89 | J24: 0.74 | K24: 0.89 | L24: 0.88 | M24: 0.9 | N24: 0.79 | O24: 0.8 | P24: 0.88 | Q24: 0.85 | R24: 0.9 | S24: 0.84 | T24: 0.86 | U24: 0.93 | V24: 0.84 | W24: 0.69 | X24: 0.84 | Y24: 0.83 | Z24: 0.92 | AA24: 0.92 | AD24: es-CL | AE24: =VLOOKUP(AD24,GroupLabels!$E$2:$H$145,3,0) -> Chile - Spanish
A25: Colombia - Spanish | B25: 0.85 | C25: 0.74 | D25: 0.87 | E25: 0.73 | F25: 0.74 | G25: 0.83 | H25: 0.86 | I25: 0.88 | J25: 0.8 | K25: 0.85 | L25: 0.86 | M25: 0.91 | N25: 0.82 | O25: 0.77 | P25: 0.89 | Q25: 0.86 | R25: 0.91 | S25: 0.85 | T25: 0.83 | U25: 0.91 | V25: 0.82 | W25: 0.66 | X25: 0.82 | Y25: 0.82 | Z25: 0.9 | AA25: 0.91 | AD25: es-CO | AE25: =VLOOKUP(AD25,GroupLabels!$E$2:$H$145,3,0) -> Colombia - Spanish
A26: Costa Rica - Spanish | B26: a | C26: a | D26: 0.88 | E26: 0.77 | F26: 0.76 | G26: 0.81 | H26: a | I26: 0.86 | J26: 0.79 | K26: 0.81 | L26: 0.82 | M26: 0.88 | N26: 0.79 | O26: 0.74 | P26: 0.87 | Q26: 0.84 | R26: a | S26: 0.83 | T26: 0.8 | U26: 0.92 | V26: 0.83 | W26: 0.77 | X26: 0.78 | Y26: 0.8 | Z26: 0.9 | AA26: 0.89 | AD26: es-CR | AE26: =VLOOKUP(AD26,GroupLabels!$E$2:$H$145,3,0) -> Costa Rica - Spanish
A27: Croatia - Croatian | B27: 0.63 | C27: 0.5 | D27: 0.9 | E27: 0.8 | F27: 0.75 | G27: 0.87 | H27: 0.84 | I27: 0.88 | J27: 0.73 | K27: 0.89 | L27: 0.87 | M27: 0.92 | N27: 0.8 | O27: 0.81 | P27: 0.89 | Q27: 0.85 | R27: 0.87 | S27: 0.87 | T27: 0.83 | U27: 0.93 | V27: 0.85 | W27: 0.74 | X27: 0.84 | Y27: 0.78 | Z27: 0.9 | AA27: 0.89 | AD27: hr-HR | AE27: =VLOOKUP(AD27,GroupLabels!$E$2:$H$145,3,0) -> Croatia - Croatian
A28: Cyprus - English* | B28: 0.8 | C28: 0.66 | D28: 0.88 | E28: 0.76 | F28: 0.86 | G28: 0.86 | H28: 0.84 | I28: 0.88 | J28: 0.76 | K28: 0.91 | L28: 0.88 | M28: 0.88 | N28: 0.83 | O28: 0.8 | P28: 0.9 | Q28: 0.83 | R28: 0.87 | S28: 0.9 | T28: 0.81 | U28: 0.95 | V28: 0.84 | W28: 0.76 | X28: 0.82 | Y28: 0.72 | Z28: 0.93 | AA28: 0.88 | AD28: en-CY | AE28: =VLOOKUP(AD28,GroupLabels!$E$2:$H$145,3,0) -> Cyprus - English*
A29: Cyprus - Modern Greek* | B29: 0.8 | C29: 0.7 | D29: 0.88 | E29: 0.76 | F29: 0.88 | G29: 0.84 | H29: 0.85 | I29: 0.86 | J29: 0.78 | K29: 0.9 | L29: 0.89 | M29: 0.91 | N29: 0.81 | O29: 0.85 | P29: 0.9 | Q29: 0.85 | R29: 0.89 | S29: 0.87 | T29: 0.82 | U29: 0.92 | V29: 0.86 | W29: 0.77 | X29: 0.83 | Y29: 0.8 | Z29: 0.93 | AA29: 0.9 | AD29: el-CY | AE29: =VLOOKUP(AD29,GroupLabels!$E$2:$H$145,3,0) -> Cyprus - Modern Greek*
A30: Czechia - Czech | B30: 0.73 | C30: 0.5 | D30: 0.87 | E30: 0.79 | F30: 0.75 | G30: 0.8 | H30: 0.82 | I30: 0.81 | J30: 0.74 | K30: 0.87 | L30: 0.84 | M30: 0.92 | N30: 0.74 | O30: 0.74 | P30: 0.87 | Q30: 0.78 | R30: 0.87 | S30: 0.84 | T30: 0.79 | U30: 0.91 | V30: 0.8 | W30: 0.73 | X30: 0.82 | Y30: 0.68 | Z30: 0.88 | AA30: 0.87 | AD30: cs-CZ | AE30: =VLOOKUP(AD30,GroupLabels!$E$2:$H$145,3,0) -> Czechia - Czech
A31: Denmark - Danish | B31: 0.68 | C31: 0.5 | D31: 0.9 | E31: 0.79 | F31: 0.77 | G31: 0.83 | H31: 0.82 | I31: 0.81 | J31: 0.8 | K31: 0.86 | L31: 0.86 | M31: 0.86 | N31: 0.76 | O31: 0.75 | P31: 0.85 | Q31: 0.76 | R31: 0.85 | S31: a | T31: 0.8 | U31: 0.94 | V31: 0.73 | W31: 0.79 | X31: 0.76 | Y31: 0.65 | Z31: 0.89 | AA31: 0.85 | AD31: da-DK | AE31: =VLOOKUP(AD31,GroupLabels!$E$2:$H$145,3,0) -> Denmark - Danish
A32: Denmark - Faroese | B32: 0.57 | C32: 0.5 | D32: 0.86 | E32: 0.84 | F32: 0.78 | G32: 0.81 | H32: 0.8 | I32: 0.76 | J32: 0.78 | K32: 0.85 | L32: 0.85 | M32: 0.79 | N32: 0.72 | O32: 0.72 | P32: 0.8 | Q32: 0.67 | R32: 0.86 | S32: a | T32: 0.77 | U32: 0.92 | V32: 0.77 | W32: 0.75 | X32: 0.69 | Y32: 0.8 | Z32: 0.86 | AA32: 0.75 | AD32: fo-DK | AE32: =VLOOKUP(AD32,GroupLabels!$E$2:$H$145,3,0) -> Denmark - Faroese
A33: Dominican Republic - Spanish | B33: 0.83 | C33: 0.72 | D33: 0.86 | E33: 0.7 | F33: 0.73 | G33: 0.8 | H33: 0.85 | I33: 0.86 | J33: 0.8 | K33: 0.87 | L33: 0.85 | M33: 0.91 | N33: 0.78 | O33: 0.77 | P33: 0.89 | Q33: 0.88 | R33: 0.89 | S33: 0.78 | T33: 0.83 | U33: 0.91 | V33: 0.83 | W33: 0.81 | X33: 0.84 | Y33: 0.8 | Z33: 0.88 | AA33: 0.91 | AD33: es-DO | AE33: =VLOOKUP(AD33,GroupLabels!$E$2:$H$145,3,0) -> Dominican Republic - Spanish
A34: Dushanbe (Tajikistan) - Russian | B34: 0.76 | C34: 0.72 | D34: a | E34: 0.69 | F34: 0.63 | G34: a | H34: 0.82 | I34: 0.8 | J34: 0.7 | K34: a | L34: 0.8 | M34: 0.84 | N34: a | O34: 0.76 | P34: 0.88 | Q34: 0.75 | R34: 0.89 | S34: 0.87 | T34: a | U34: 0.86 | V34: 0.74 | W34: 0.59 | X34: 0.8 | Y34: a | Z34: a | AA34: 0.85 | AD34: ru-TJ | AE34: =VLOOKUP(AD34,GroupLabels!$E$2:$H$145,3,0) -> Dushanbe (Tajikistan) - Russian
A35: Dushanbe (Tajikistan) - Tajik | B35: 0.74 | C35: 0.72 | D35: a | E35: 0.67 | F35: 0.79 | G35: a | H35: 0.89 | I35: 0.81 | J35: 0.8 | K35: a | L35: 0.86 | M35: 0.89 | N35: a | O35: 0.8 | P35: 0.88 | Q35: 0.81 | R35: 0.92 | S35: 0.91 | T35: a | U35: 0.9 | V35: 0.81 | W35: 0.85 | X35: 0.9 | Y35: a | Z35: a | AA35: 0.84 | AD35: tg-TJ | AE35: =VLOOKUP(AD35,GroupLabels!$E$2:$H$145,3,0) -> Dushanbe (Tajikistan) - Tajik
A36: Ecuador - Spanish | B36: 0.85 | C36: 0.72 | D36: 0.87 | E36: 0.68 | F36: 0.7 | G36: 0.79 | H36: 0.85 | I36: 0.87 | J36: 0.78 | K36: 0.84 | L36: 0.84 | M36: 0.91 | N36: 0.78 | O36: 0.75 | P36: 0.87 | Q36: 0.84 | R36: 0.89 | S36: 0.8 | T36: 0.82 | U36: 0.93 | V36: 0.8 | W36: 0.67 | X36: 0.79 | Y36: 0.8 | Z36: 0.9 | AA36: 0.89 | AD36: es-EC | AE36: =VLOOKUP(AD36,GroupLabels!$E$2:$H$145,3,0) -> Ecuador - Spanish
A37: El Salvador - Spanish | B37: 0.79 | C37: 0.59 | D37: 0.89 | E37: 0.72 | F37: 0.75 | G37: 0.86 | H37: 0.88 | I37: 0.88 | J37: 0.82 | K37: 0.88 | L37: 0.87 | M37: 0.93 | N37: 0.85 | O37: 0.8 | P37: 0.9 | Q37: 0.88 | R37: 0.91 | S37: 0.86 | T37: 0.86 | U37: 0.93 | V37: 0.82 | W37: 0.83 | X37: 0.85 | Y37: 0.82 | Z37: 0.91 | AA37: 0.92 | AD37: es-SV | AE37: =VLOOKUP(AD37,GroupLabels!$E$2:$H$145,3,0) -> El Salvador - Spanish
A38: Estonia - Estonian | B38: 0.68 | C38: 0.49 | D38: 0.86 | E38: 0.78 | F38: 0.77 | G38: 0.84 | H38: 0.79 | I38: 0.8 | J38: 0.79 | K38: 0.88 | L38: 0.82 | M38: 0.88 | N38: 0.8 | O38: 0.74 | P38: 0.83 | Q38: 0.75 | R38: 0.88 | S38: 0.87 | T38: 0.78 | U38: 0.92 | V38: 0.76 | W38: 0.76 | X38: 0.78 | Y38: 0.72 | Z38: 0.9 | AA38: 0.8 | AD38: et-EE | AE38: =VLOOKUP(AD38,GroupLabels!$E$2:$H$145,3,0) -> Estonia - Estonian
A39: Estonia - Russian | B39: 0.69 | C39: 0.54 | D39: 0.84 | E39: 0.81 | F39: 0.78 | G39: 0.85 | H39: 0.83 | I39: 0.86 | J39: 0.82 | K39: 0.89 | L39: 0.84 | M39: 0.86 | N39: 0.77 | O39: 0.77 | P39: 0.86 | Q39: 0.79 | R39: 0.89 | S39: 0.88 | T39: 0.76 | U39: 0.9 | V39: 0.81 | W39: 0.72 | X39: 0.83 | Y39: 0.69 | Z39: 0.87 | AA39: 0.87 | AD39: ru-EE | AE39: =VLOOKUP(AD39,GroupLabels!$E$2:$H$145,3,0) -> Estonia - Russian
A40: Finland - Finnish | B40: 0.64 | C40: 0.51 | D40: 0.92 | E40: 0.84 | F40: 0.85 | G40: 0.86 | H40: 0.83 | I40: 0.9 | J40: 0.78 | K40: 0.9 | L40: 0.89 | M40: 0.91 | N40: 0.83 | O40: 0.79 | P40: 0.9 | Q40: 0.85 | R40: 0.91 | S40: 0.89 | T40: 0.84 | U40: 0.94 | V40: 0.82 | W40: 0.8 | X40: 0.77 | Y40: 0.78 | Z40: 0.92 | AA40: 0.91 | AD40: fi-FI | AE40: =VLOOKUP(AD40,GroupLabels!$E$2:$H$145,3,0) -> Finland - Finnish
A41: Finland - Swedish | B41: 0.65 | C41: 0.56 | D41: 0.91 | E41: 0.84 | F41: 0.82 | G41: 0.86 | H41: 0.84 | I41: 0.88 | J41: 0.79 | K41: 0.88 | L41: 0.87 | M41: 0.91 | N41: 0.85 | O41: 0.73 | P41: 0.89 | Q41: 0.84 | R41: 0.89 | S41: 0.89 | T41: 0.84 | U41: 0.93 | V41: 0.79 | W41: 0.67 | X41: 0.8 | Y41: 0.77 | Z41: 0.9 | AA41: 0.89 | AD41: sv-FI | AE41: =VLOOKUP(AD41,GroupLabels!$E$2:$H$145,3,0) -> Finland - Swedish
A42: France - French | B42: 0.7 | C42: 0.57 | D42: 0.86 | E42: 0.71 | F42: 0.78 | G42: 0.81 | H42: 0.82 | I42: 0.87 | J42: 0.78 | K42: 0.88 | L42: 0.86 | M42: 0.87 | N42: 0.79 | O42: 0.75 | P42: 0.89 | Q42: 0.79 | R42: 0.84 | S42: 0.87 | T42: 0.8 | U42: 0.91 | V42: 0.81 | W42: 0.76 | X42: 0.71 | Y42: 0.74 | Z42: 0.9 | AA42: 0.86 | AD42: fr-FR | AE42: =VLOOKUP(AD42,GroupLabels!$E$2:$H$145,3,0) -> France - French
A43: Georgia - Azerbaijani | B43: 0.65 | C43: 0.55 | D43: 0.85 | E43: 0.66 | F43: 0.81 | G43: 0.85 | H43: 0.84 | I43: 0.87 | J43: 0.82 | K43: 0.87 | L43: 0.88 | M43: 0.87 | N43: 0.82 | O43: 0.84 | P43: 0.89 | Q43: 0.88 | R43: 0.87 | S43: 0.9 | T43: 0.8 | U43: 0.93 | V43: 0.86 | W43: 0.86 | X43: 0.8 | Y43: 0.83 | Z43: 0.86 | AA43: 0.89 | AD43: az-GE | AE43: =VLOOKUP(AD43,GroupLabels!$E$2:$H$145,3,0) -> Georgia - Azerbaijani
...

Sheet T22.A.12
A1: Table of Contents
A3: Table 22.A.12
A4: Number of items with international parameters for the IRT scales in the Student Questionnaire
A6: Country/economy (language group) | B6: HOMEPOS | C6: ICTRES | D6: AIUSESCH | E6: BELONG | F6: BULLIED | G6: COGABIL | H6: COGACSC | I6: COLLENEFF | J6: CURIO | K6: DISCLISCI | L6: EFFSCIE | M6: ENGSCIPR | N6: ENPROBS | O6: ENVAPART | P6: ENVAWARE | Q6: ENVCAPCH | R6: FAMSUP | S6: FEELSAFE | T6: GOALSET | U6: JOYSCIE | V6: OPENVLRN | W6: PERSEV | X6: SCIECOLLR | Y6: SELFREG | Z6: STBELSCIE | AA6: TEACHSUP
A7: Albania - Albanian | B7: 22 | C7: 10 | D7: 4 | E7: 6 | F7: 5 | G7: 4 | H7: 5 | I7: 4 | J7: 5 | K7: 6 | L7: 6 | M7: 6 | N7: 4 | O7: 5 | P7: 6 | Q7: 4 | R7: 5 | S7: 4 | T7: 4 | U7: 4 | V7: 4 | W7: 6 | X7: 4 | Y7: 4 | Z7: 5 | AA7: 5 | AD7: sq-AL | AE7: =VLOOKUP(AD7,GroupLabels!$E$2:$H$145,3,0) -> Albania - Albanian
A8: Argentina - Spanish | B8: 21 | C8: 10 | D8: 4 | E8: 6 | F8: 5 | G8: 4 | H8: 5 | I8: 4 | J8: 5 | K8: 6 | L8: 6 | M8: 6 | N8: 4 | O8: 5 | P8: 6 | Q8: 4 | R8: 5 | S8: 4 | T8: 4 | U8: 4 | V8: 4 | W8: 6 | X8: 4 | Y8: 4 | Z8: 5 | AA8: 5 | AD8: es-AR | AE8: =VLOOKUP(AD8,GroupLabels!$E$2:$H$145,3,0) -> Argentina - Spanish
A9: Armenia - Armenian | B9: 22 | C9: 9 | D9: 4 | E9: 6 | F9: 5 | G9: 4 | H9: 5 | I9: 4 | J9: 5 | K9: 6 | L9: 6 | M9: 6 | N9: 4 | O9: 5 | P9: 6 | Q9: 4 | R9: 5 | S9: 4 | T9: 4 | U9: 4 | V9: 4 | W9: 6 | X9: 4 | Y9: 4 | Z9: 5 | AA9: 5 | AD9: hy-AM | AE9: =VLOOKUP(AD9,GroupLabels!$E$2:$H$145,3,0) -> Armenia - Armenian
A10: Australia - English | B10: 21 | C10: 9 | D10: 4 | E10: 6 | F10: 5 | G10: 4 | H10: 5 | I10: 4 | J10: 5 | K10: 6 | L10: 6 | M10: 6 | N10: 4 | O10: 5 | P10: 6 | Q10: 4 | R10: 5 | S10: 4 | T10: 4 | U10: 4 | V10: 4 | W10: 6 | X10: 4 | Y10: 4 | Z10: 5 | AA10: 5 | AD10: en-AU | AE10: =VLOOKUP(AD10,GroupLabels!$E$2:$H$145,3,0) -> Australia - English
A11: Austria - German | B11: 22 | C11: 9 | D11: 4 | E11: 6 | F11: 5 | G11: 4 | H11: 5 | I11: 4 | J11: 5 | K11: 6 | L11: 6 | M11: 6 | N11: 4 | O11: 5 | P11: 6 | Q11: 4 | R11: 5 | S11: 4 | T11: 4 | U11: 4 | V11: 4 | W11: 6 | X11: 4 | Y11: 4 | Z11: 5 | AA11: 5 | AD11: de-AT | AE11: =VLOOKUP(AD11,GroupLabels!$E$2:$H$145,3,0) -> Austria - German
A12: Azerbaijan - Azerbaijani | B12: 22 | C12: 10 | D12: 4 | E12: 6 | F12: 5 | G12: 4 | H12: 5 | I12: 4 | J12: 5 | K12: 6 | L12: 6 | M12: 6 | N12: 4 | O12: 5 | P12: 6 | Q12: 4 | R12: 5 | S12: 4 | T12: 4 | U12: 4 | V12: 4 | W12: 6 | X12: 4 | Y12: 4 | Z12: 5 | AA12: 5 | AD12: az-QZ | AE12: =VLOOKUP(AD12,GroupLabels!$E$2:$H$145,3,0) -> Azerbaijan - Azerbaijani
A13: Azerbaijan - Russian | B13: 22 | C13: 9 | D13: 4 | E13: 6 | F13: 5 | G13: 4 | H13: 5 | I13: 4 | J13: 5 | K13: 6 | L13: 6 | M13: 6 | N13: 4 | O13: 5 | P13: 6 | Q13: 4 | R13: 5 | S13: 4 | T13: 4 | U13: 4 | V13: 4 | W13: 6 | X13: 4 | Y13: 4 | Z13: 5 | AA13: 5 | AD13: ru-QZ | AE13: =VLOOKUP(AD13,GroupLabels!$E$2:$H$145,3,0) -> Azerbaijan - Russian
A14: B-S-J-G (China) - Chinese* | B14: 22 | C14: 10 | D14: 4 | E14: 6 | F14: 5 | G14: 4 | H14: 5 | I14: 4 | J14: 5 | K14: 6 | L14: 6 | M14: 6 | N14: 4 | O14: 5 | P14: 6 | Q14: 4 | R14: 5 | S14: 4 | T14: 4 | U14: 4 | V14: 4 | W14: 6 | X14: 4 | Y14: 4 | Z14: 5 | AA14: 5 | AD14: zh-CN | AE14: =VLOOKUP(AD14,GroupLabels!$E$2:$H$145,3,0) -> B-S-J-G (China) - Chinese*
A15: Belgium (Flemish Community) - Dutch | B15: 22 | C15: 10 | D15: 4 | E15: 6 | F15: 5 | G15: 4 | H15: 5 | I15: 4 | J15: 5 | K15: 6 | L15: 6 | M15: 6 | N15: 4 | O15: 5 | P15: 6 | Q15: 4 | R15: 5 | S15: 4 | T15: 4 | U15: 4 | V15: 4 | W15: 6 | X15: 4 | Y15: 4 | Z15: 5 | AA15: 5 | AD15: nl-BE | AE15: =VLOOKUP(AD15,GroupLabels!$E$2:$H$145,3,0) -> Belgium (Flemish Community) - Dutch
A16: Belgium (French Community) - French | B16: 22 | C16: 9 | D16: 4 | E16: 6 | F16: 5 | G16: 4 | H16: 5 | I16: 4 | J16: 5 | K16: 6 | L16: 6 | M16: 6 | N16: 4 | O16: 5 | P16: 6 | Q16: 4 | R16: 5 | S16: 4 | T16: 4 | U16: 4 | V16: 4 | W16: 6 | X16: 4 | Y16: 4 | Z16: 5 | AA16: 5 | AD16: fr-BE | AE16: =VLOOKUP(AD16,GroupLabels!$E$2:$H$145,3,0) -> Belgium (French Community) - French
A17: Belgium (French Community) - German | B17: 22 | C17: 9 | D17: 4 | E17: 6 | F17: 5 | G17: 4 | H17: 5 | I17: 4 | J17: 5 | K17: 6 | L17: 6 | M17: 6 | N17: 4 | O17: 5 | P17: 6 | Q17: 4 | R17: 5 | S17: 4 | T17: 4 | U17: 4 | V17: 4 | W17: 6 | X17: 4 | Y17: 4 | Z17: 5 | AA17: 5 | AD17: de-BE | AE17: =VLOOKUP(AD17,GroupLabels!$E$2:$H$145,3,0) -> Belgium (French Community) - German
A18: Brazil - Portuguese | B18: 22 | C18: 9 | D18: 4 | E18: 6 | F18: 5 | G18: 4 | H18: 5 | I18: 4 | J18: 5 | K18: 6 | L18: 6 | M18: 6 | N18: 4 | O18: 5 | P18: 6 | Q18: 4 | R18: 5 | S18: 4 | T18: 4 | U18: 4 | V18: 4 | W18: 6 | X18: 4 | Y18: 4 | Z18: 5 | AA18: 5 | AD18: pt-BR | AE18: =VLOOKUP(AD18,GroupLabels!$E$2:$H$145,3,0) -> Brazil - Portuguese
... A20: Bulgaria - Bulgarian | B20: 21 | C20: 10 | D20: 4 | E20: 6 | F20: 5 | G20: 4 | H20: 5 | I20: 4 | J20: 5 | K20: 6 | L20: 6 | M20: 6 | N20: 4 | O20: 5 | P20: 6 | Q20: 4 | R20: 5 | S20: 4 | T20: 4 | U20: 4 | V20: 4 | W20: 6 | X20: 4 | Y20: 4 | Z20: 5 | AA20: 5 | AD20: bg-BG | AE20: =VLOOKUP(AD20,GroupLabels!$E$2:$H$145,3,0) -> Bulgaria - Bulgarian
A21: Cambodia - Khmer | B21: 22 | C21: 9 | D21: a | E21: 6 | F21: 5 | G21: a | H21: 5 | I21: 4 | J21: 5 | K21: a | L21: 6 | M21: 6 | N21: a | O21: 5 | P21: 6 | Q21: 4 | R21: 5 | S21: 4 | T21: a | U21: 4 | V21: 4 | W21: 6 | X21: 4 | Y21: a | Z21: 5 | AA21: a | AD21: km-KH | AE21: =VLOOKUP(AD21,GroupLabels!$E$2:$H$145,3,0) -> Cambodia - Khmer
A22: Canada - English | B22: 22 | C22: 10 | D22: 4 | E22: 6 | F22: 5 | G22: 4 | H22: 5 | I22: 4 | J22: 5 | K22: 6 | L22: 6 | M22: 6 | N22: 4 | O22: 5 | P22: 6 | Q22: 4 | R22: 5 | S22: 4 | T22: 4 | U22: 4 | V22: 4 | W22: 6 | X22: 4 | Y22: 4 | Z22: 5 | AA22: a | AD22: en-CA | AE22: =VLOOKUP(AD22,GroupLabels!$E$2:$H$145,3,0) -> Canada - English
A23: Canada - French | B23: 19 | C23: 10 | D23: 4 | E23: 6 | F23: 5 | G23: 4 | H23: 5 | I23: 4 | J23: 5 | K23: 6 | L23: 6 | M23: 6 | N23: 4 | O23: 5 | P23: 6 | Q23: 4 | R23: 5 | S23: 4 | T23: 4 | U23: 4 | V23: 4 | W23: 6 | X23: 4 | Y23: 4 | Z23: 5 | AA23: a | AD23: fr-CA | AE23: =VLOOKUP(AD23,GroupLabels!$E$2:$H$145,3,0) -> Canada - French
A24: Chile - Spanish | B24: 21 | C24: 10 | D24: 4 | E24: 6 | F24: 5 | G24: 4 | H24: 5 | I24: 4 | J24: 5 | K24: 6 | L24: 6 | M24: 6 | N24: 4 | O24: 5 | P24: 6 | Q24: 4 | R24: 5 | S24: 4 | T24: 4 | U24: 4 | V24: 4 | W24: 6 | X24: 4 | Y24: 4 | Z24: 5 | AA24: 5 | AD24: es-CL | AE24: =VLOOKUP(AD24,GroupLabels!$E$2:$H$145,3,0) -> Chile - Spanish
A25: Colombia - Spanish | B25: 19 | C25: 9 | D25: 4 | E25: 6 | F25: 5 | G25: 4 | H25: 5 | I25: 4 | J25: 5 | K25: 6 | L25: 6 | M25: 6 | N25: 4 | O25: 5 | P25: 6 | Q25: 4 | R25: 5 | S25: 4 | T25: 4 | U25: 4 | V25: 4 | W25: 6 | X25: 4 | Y25: 4 | Z25: 5 | AA25: 5 | AD25: es-CO | AE25: =VLOOKUP(AD25,GroupLabels!$E$2:$H$145,3,0) -> Colombia - Spanish
A26: Costa Rica - Spanish | B26: a | C26: a | D26: 4 | E26: 6 | F26: 5 | G26: 4 | H26: a | I26: 4 | J26: 5 | K26: 6 | L26: 6 | M26: 6 | N26: 4 | O26: 5 | P26: 6 | Q26: 4 | R26: a | S26: 4 | T26: 4 | U26: 4 | V26: 4 | W26: 6 | X26: 4 | Y26: 4 | Z26: 5 | AA26: 5 | AD26: es-CR | AE26: =VLOOKUP(AD26,GroupLabels!$E$2:$H$145,3,0) -> Costa Rica - Spanish
A27: Croatia - Croatian | B27: 22 | C27: 9 | D27: 4 | E27: 6 | F27: 5 | G27: 4 | H27: 5 | I27: 4 | J27: 5 | K27: 6 | L27: 6 | M27: 6 | N27: 4 | O27: 5 | P27: 6 | Q27: 4 | R27: 5 | S27: 4 | T27: 4 | U27: 4 | V27: 4 | W27: 6 | X27: 4 | Y27: 4 | Z27: 5 | AA27: 5 | AD27: hr-HR | AE27: =VLOOKUP(AD27,GroupLabels!$E$2:$H$145,3,0) -> Croatia - Croatian
A28: Cyprus - English* | B28: 22 | C28: 9 | D28: 4 | E28: 6 | F28: 5 | G28: 4 | H28: 5 | I28: 4 | J28: 5 | K28: 6 | L28: 6 | M28: 6 | N28: 4 | O28: 5 | P28: 6 | Q28: 4 | R28: 5 | S28: 4 | T28: 4 | U28: 4 | V28: 4 | W28: 6 | X28: 4 | Y28: 4 | Z28: 5 | AA28: 5 | AD28: en-CY | AE28: =VLOOKUP(AD28,GroupLabels!$E$2:$H$145,3,0) -> Cyprus - English*
A29: Cyprus - Modern Greek* | B29: 22 | C29: 10 | D29: 4 | E29: 6 | F29: 5 | G29: 4 | H29: 5 | I29: 4 | J29: 5 | K29: 6 | L29: 6 | M29: 6 | N29: 4 | O29: 5 | P29: 6 | Q29: 4 | R29: 5 | S29: 4 | T29: 4 | U29: 4 | V29: 4 | W29: 6 | X29: 4 | Y29: 4 | Z29: 5 | AA29: 5 | AD29: el-CY | AE29: =VLOOKUP(AD29,GroupLabels!$E$2:$H$145,3,0) -> Cyprus - Modern Greek*
A30: Czechia - Czech | B30: 21 | C30: 9 | D30: 4 | E30: 6 | F30: 5 | G30: 4 | H30: 5 | I30: 4 | J30: 5 | K30: 6 | L30: 6 | M30: 6 | N30: 4 | O30: 5 | P30: 6 | Q30: 4 | R30: 5 | S30: 4 | T30: 4 | U30: 4 | V30: 4 | W30: 6 | X30: 4 | Y30: 4 | Z30: 5 | AA30: 5 | AD30: cs-CZ | AE30: =VLOOKUP(AD30,GroupLabels!$E$2:$H$145,3,0) -> Czechia - Czech
A31: Denmark - Danish | B31: 20 | C31: 9 | D31: 4 | E31: 6 | F31: 5 | G31: 4 | H31: 5 | I31: 4 | J31: 5 | K31: 6 | L31: 6 | M31: 6 | N31: 4 | O31: 5 | P31: 6 | Q31: 4 | R31: 5 | S31: a | T31: 4 | U31: 4 | V31: 4 | W31: 6 | X31: 4 | Y31: 4 | Z31: 5 | AA31: 5 | AD31: da-DK | AE31: =VLOOKUP(AD31,GroupLabels!$E$2:$H$145,3,0) -> Denmark - Danish
A32: Denmark - Faroese | B32: 19 | C32: 9 | D32: 4 | E32: 6 | F32: 5 | G32: 4 | H32: 5 | I32: 4 | J32: 5 | K32: 6 | L32: 6 | M32: 6 | N32: 4 | O32: 5 | P32: 6 | Q32: 4 | R32: 5 | S32: a | T32: 4 | U32: 4 | V32: 4 | W32: 6 | X32: 4 | Y32: 4 | Z32: 5 | AA32: 5 | AD32: fo-DK | AE32: =VLOOKUP(AD32,GroupLabels!$E$2:$H$145,3,0) -> Denmark - Faroese
A33: Dominican Republic - Spanish | B33: 21 | C33: 9 | D33: 4 | E33: 6 | F33: 5 | G33: 4 | H33: 5 | I33: 4 | J33: 5 | K33: 6 | L33: 6 | M33: 6 | N33: 4 | O33: 5 | P33: 6 | Q33: 4 | R33: 5 | S33: 4 | T33: 4 | U33: 4 | V33: 4 | W33: 6 | X33: 4 | Y33: 4 | Z33: 5 | AA33: 5 | AD33: es-DO | AE33: =VLOOKUP(AD33,GroupLabels!$E$2:$H$145,3,0) -> Dominican Republic - Spanish
A34: Dushanbe (Tajikistan) - Russian | B34: 22 | C34: 10 | D34: a | E34: 6 | F34: 5 | G34: a | H34: 5 | I34: 4 | J34: 5 | K34: a | L34: 6 | M34: 6 | N34: a | O34: 5 | P34: 6 | Q34: 4 | R34: 5 | S34: 4 | T34: a | U34: 4 | V34: 4 | W34: 6 | X34: 4 | Y34: a | Z34: 5 | AA34: a | AD34: ru-TJ | AE34: =VLOOKUP(AD34,GroupLabels!$E$2:$H$145,3,0) -> Dushanbe (Tajikistan) - Russian
A35: Dushanbe (Tajikistan) - Tajik | B35: 20 | C35: 10 | D35: a | E35: 6 | F35: 5 | G35: a | H35: 5 | I35: 4 | J35: 5 | K35: a | L35: 6 | M35: 6 | N35: a | O35: 5 | P35: 6 | Q35: 4 | R35: 5 | S35: 4 | T35: a | U35: 4 | V35: 4 | W35: 6 | X35: 4 | Y35: a | Z35: 5 | AA35: a | AD35: tg-TJ | AE35: =VLOOKUP(AD35,GroupLabels!$E$2:$H$145,3,0) -> Dushanbe (Tajikistan) - Tajik
A36: Ecuador - Spanish | B36: 21 | C36: 9 | D36: 4 | E36: 6 | F36: 5 | G36: 4 | H36: 5 | I36: 4 | J36: 5 | K36: 6 | L36: 6 | M36: 6 | N36: 4 | O36: 5 | P36: 6 | Q36: 4 | R36: 5 | S36: 4 | T36: 4 | U36: 4 | V36: 4 | W36: 6 | X36: 4 | Y36: 4 | Z36: 5 | AA36: 5 | AD36: es-EC | AE36: =VLOOKUP(AD36,GroupLabels!$E$2:$H$145,3,0) -> Ecuador - Spanish
A37: El Salvador - Spanish | B37: 21 | C37: 9 | D37: 4 | E37: 6 | F37: 5 | G37: 4 | H37: 5 | I37: 4 | J37: 5 | K37: 6 | L37: 6 | M37: 6 | N37: 4 | O37: 5 | P37: 6 | Q37: 4 | R37: 5 | S37: 4 | T37: 4 | U37: 4 | V37: 4 | W37: 6 | X37: 4 | Y37: 4 | Z37: 5 | AA37: 5 | AD37: es-SV | AE37: =VLOOKUP(AD37,GroupLabels!$E$2:$H$145,3,0) -> El Salvador - Spanish
A38: Estonia - Estonian | B38: 22 | C38: 9 | D38: 4 | E38: 6 | F38: 5 | G38: 4 | H38: 5 | I38: 4 | J38: 5 | K38: 6 | L38: 6 | M38: 6 | N38: 4 | O38: 5 | P38: 6 | Q38: 4 | R38: 5 | S38: 4 | T38: 4 | U38: 4 | V38: 4 | W38: 6 | X38: 4 | Y38: 4 | Z38: 5 | AA38: 5 | AD38: et-EE | AE38: =VLOOKUP(AD38,GroupLabels!$E$2:$H$145,3,0) -> Estonia - Estonian
A39: Estonia - Russian | B39: 21 | C39: 9 | D39: 4 | E39: 6 | F39: 5 | G39: 4 | H39: 5 | I39: 4 | J39: 5 | K39: 6 | L39: 6 | M39: 6 | N39: 4 | O39: 5 | P39: 6 | Q39: 4 | R39: 5 | S39: 4 | T39: 4 | U39: 4 | V39: 4 | W39: 6 | X39: 4 | Y39: 4 | Z39: 5 | AA39: 5 | AD39: ru-EE | AE39: =VLOOKUP(AD39,GroupLabels!$E$2:$H$145,3,0) -> Estonia - Russian
A40: Finland - Finnish | B40: 21 | C40: 10 | D40: 4 | E40: 6 | F40: 5 | G40: 4 | H40: 5 | I40: 4 | J40: 5 | K40: 6 | L40: 6 | M40: 6 | N40: 4 | O40: 5 | P40: 6 | Q40: 4 | R40: 5 | S40: 4 | T40: 4 | U40: 4 | V40: 4 | W40: 6 | X40: 4 | Y40: 4 | Z40: 5 | AA40: 5 | AD40: fi-FI | AE40: =VLOOKUP(AD40,GroupLabels!$E$2:$H$145,3,0) -> Finland - Finnish
A41: Finland - Swedish | B41: 20 | C41: 9 | D41: 4 | E41: 6 | F41: 5 | G41: 4 | H41: 5 | I41: 4 | J41: 5 | K41: 6 | L41: 6 | M41: 6 | N41: 4 | O41: 5 | P41: 6 | Q41: 4 | R41: 5 | S41: 4 | T41: 4 | U41: 4 | V41: 4 | W41: 6 | X41: 4 | Y41: 4 | Z41: 5 | AA41: 5 | AD41: sv-FI | AE41: =VLOOKUP(AD41,GroupLabels!$E$2:$H$145,3,0) -> Finland - Swedish
A42: France - French | B42: 20 | C42: 9 | D42: 4 | E42: 6 | F42: 5 | G42: 4 | H42: 5 | I42: 4 | J42: 5 | K42: 6 | L42: 6 | M42: 6 | N42: 4 | O42: 5 | P42: 6 | Q42: 4 | R42: 5 | S42: 4 | T42: 4 | U42: 4 | V42: 4 | W42: 6 | X42: 4 | Y42: 4 | Z42: 5 | AA42: 5 | AD42: fr-FR | AE42: =VLOOKUP(AD42,GroupLabels!$E$2:$H$145,3,0) -> France - French
A43: Georgia - Azerbaijani | B43: 20 | C43: 9 | D43: 4 | E43: 6 | F43: 5 | G43: 4 | H43: 5 | I43: 4 | J43: 5 | K43: 6 | L43: 6 | M43: 6 | N43: 4 | O43: 5 | P43: 6 | Q43: 4 | R43: 5 | S43: 4 | T43: 4 | U43: 4 | V43: 4 | W43: 6 | X43: 4 | Y43: 4 | Z43: 5 | AA43: 5 | AD43: az-GE | AE43: =VLOOKUP(AD43,GroupLabels!$E$2:$H$145,3,0) -> Georgia - Azerbaijani
...

Sheet T22.A.13
A1: Table of Contents
A3: Table 22.A.13
A4: Number of trend items with international parameters for the trend IRT scales in the Student Questionnaire
A6: Country/economy (language group) | B6: ICTRES | C6: BELONG | D6: BULLIED | E6: FEELSAFE | F6: DISCLISCI | G6: TEACHSUP | H6: JOYSCIE | I6: ENVAWARE | J6: FAMSUP
A7: Albania - Albanian | B7: 8 | C7: 6 | D7: 4 | E7: 4 | F7: 5 | G7: 5 | H7: 4 | I7: 5 | J7: 5 | AC7: sq-AL | AD7: =VLOOKUP(AC7,GroupLabels!$E$2:$H$145,3,0) -> Albania - Albanian
A8: Argentina - Spanish | B8: 8 | C8: 6 | D8: 4 | E8: 4 | F8: 5 | G8: 5 | H8: 4 | I8: 5 | J8: 5 | AC8: es-AR | AD8: =VLOOKUP(AC8,GroupLabels!$E$2:$H$145,3,0) -> Argentina - Spanish
A9: Armenia - Armenian | B9: 8 | C9: 6 | D9: 4 | E9: 4 | F9: 5 | G9: 5 | H9: 4 | I9: 5 | J9: 5 | AC9: hy-AM | AD9: =VLOOKUP(AC9,GroupLabels!$E$2:$H$145,3,0) -> Armenia - Armenian
A10: Australia - English | B10: 8 | C10: 6 | D10: 4 | E10: 4 | F10: 5 | G10: 5 | H10: 4 | I10: 5 | J10: 5 | AC10: en-AU | AD10: =VLOOKUP(AC10,GroupLabels!$E$2:$H$145,3,0) -> Australia - English
A11: Austria - German | B11: 8 | C11: 6 | D11: 4 | E11: 4 | F11: 5 | G11: 5 | H11: 4 | I11: 5 | J11: 5 | AC11: de-AT | AD11: =VLOOKUP(AC11,GroupLabels!$E$2:$H$145,3,0) -> Austria - German
A12: Azerbaijan - Azerbaijani | B12: 8 | C12: 6 | D12: 4 | E12: 4 | F12: 5 | G12: 5 | H12: 4 | I12: 5 | J12: 5 | AC12: az-QZ | AD12: =VLOOKUP(AC12,GroupLabels!$E$2:$H$145,3,0) -> Azerbaijan - Azerbaijani
A13: Azerbaijan - Russian | B13: 8 | C13: 6 | D13: 4 | E13: 4 | F13: 5 | G13: 5 | H13: 4 | I13: 5 | J13: 5 | AC13: ru-QZ | AD13: =VLOOKUP(AC13,GroupLabels!$E$2:$H$145,3,0) -> Azerbaijan - Russian
A14: B-S-J-G (China) - Chinese* | B14: 8 | C14: 6 | D14: 4 | E14: 4 | F14: 5 | G14: 5 | H14: 4 | I14: 5 | J14: 5 | AC14: zh-CN | AD14: =VLOOKUP(AC14,GroupLabels!$E$2:$H$145,3,0) -> B-S-J-G (China) - Chinese*
A15: Belgium (Flemish Community) - Dutch | B15: 8 | C15: 6 | D15: 4 | E15: 4 | F15: 5 | G15: 5 | H15: 4 | I15: 5 | J15: 5 | AC15: nl-BE | AD15: =VLOOKUP(AC15,GroupLabels!$E$2:$H$145,3,0) -> Belgium (Flemish Community) - Dutch
A16: Belgium (French Community) - French | B16: 8 | C16: 6 | D16: 4 | E16: 4 | F16: 5 | G16: 5 | H16: 4 | I16: 5 | J16: 5 | AC16: fr-BE | AD16: =VLOOKUP(AC16,GroupLabels!$E$2:$H$145,3,0) -> Belgium (French Community) - French
A17: Belgium (French Community) - German | B17: 8 | C17: 6 | D17: 4 | E17: 4 | F17: 5 | G17: 5 | H17: 4 | I17: 5 | J17: 5 | AC17: de-BE | AD17: =VLOOKUP(AC17,GroupLabels!$E$2:$H$145,3,0) -> Belgium (French Community) - German
A18: Brazil - Portuguese | B18: 8 | C18: 6 | D18: 4 | E18: 4 | F18: 5 | G18: 5 | H18: 4 | I18: 5 | J18: 5 | AC18: pt-BR | AD18: =VLOOKUP(AC18,GroupLabels!$E$2:$H$145,3,0) -> Brazil - Portuguese
... A20: Bulgaria - Bulgarian | B20: 8 | C20: 6 | D20: 4 | E20: 4 | F20: 5 | G20: 5 | H20: 4 | I20: 5 | J20: 5 | AC20: bg-BG | AD20: =VLOOKUP(AC20,GroupLabels!$E$2:$H$145,3,0) -> Bulgaria - Bulgarian
A21: Cambodia - Khmer | B21: 8 | C21: 6 | D21: 4 | E21: 4 | F21: a | G21: a | H21: 4 | I21: 5 | J21: 5 | AC21: km-KH | AD21: =VLOOKUP(AC21,GroupLabels!$E$2:$H$145,3,0) -> Cambodia - Khmer
A22: Canada - English | B22: 8 | C22: 6 | D22: 4 | E22: 4 | F22: 5 | G22: a | H22: 4 | I22: 5 | J22: 5 | AC22: en-CA | AD22: =VLOOKUP(AC22,GroupLabels!$E$2:$H$145,3,0) -> Canada - English
A23: Canada - French | B23: 8 | C23: 6 | D23: 4 | E23: 4 | F23: 5 | G23: a | H23: 4 | I23: 5 | J23: 5 | AC23: fr-CA | AD23: =VLOOKUP(AC23,GroupLabels!$E$2:$H$145,3,0) -> Canada - French
A24: Chile - Spanish | B24: 8 | C24: 6 | D24: 4 | E24: 4 | F24: 5 | G24: 5 | H24: 4 | I24: 5 | J24: 5 | AC24: es-CL | AD24: =VLOOKUP(AC24,GroupLabels!$E$2:$H$145,3,0) -> Chile - Spanish
A25: Colombia - Spanish | B25: 8 | C25: 6 | D25: 4 | E25: 4 | F25: 5 | G25: 5 | H25: 4 | I25: 5 | J25: 5 | AC25: es-CO | AD25: =VLOOKUP(AC25,GroupLabels!$E$2:$H$145,3,0) -> Colombia - Spanish
A26: Costa Rica - Spanish | B26: a | C26: 6 | D26: 4 | E26: 4 | F26: 5 | G26: 5 | H26: 4 | I26: 5 | J26: a | AC26: es-CR | AD26: =VLOOKUP(AC26,GroupLabels!$E$2:$H$145,3,0) -> Costa Rica - Spanish
A27: Croatia - Croatian | B27: 8 | C27: 6 | D27: 4 | E27: 4 | F27: 5 | G27: 5 | H27: 4 | I27: 5 | J27: 5 | AC27: hr-HR | AD27: =VLOOKUP(AC27,GroupLabels!$E$2:$H$145,3,0) -> Croatia - Croatian
A28: Cyprus - English* | B28: 8 | C28: 6 | D28: 4 | E28: 4 | F28: 5 | G28: 5 | H28: 4 | I28: 5 | J28: 5 | AC28: en-CY | AD28: =VLOOKUP(AC28,GroupLabels!$E$2:$H$145,3,0) -> Cyprus - English*
A29: Cyprus - Modern Greek* | B29: 8 | C29: 6 | D29: 4 | E29: 4 | F29: 5 | G29: 5 | H29: 4 | I29: 5 | J29: 5 | AC29: el-CY | AD29: =VLOOKUP(AC29,GroupLabels!$E$2:$H$145,3,0) -> Cyprus - Modern Greek*
A30: Czechia - Czech | B30: 8 | C30: 6 | D30: 4 | E30: 4 | F30: 5 | G30: 5 | H30: 4 | I30: 5 | J30: 5 | AC30: cs-CZ | AD30: =VLOOKUP(AC30,GroupLabels!$E$2:$H$145,3,0) -> Czechia - Czech
A31: Denmark - Danish | B31: 8 | C31: 6 | D31: 4 | E31: a | F31: 5 | G31: 5 | H31: 4 | I31: 5 | J31: 5 | AC31: da-DK | AD31: =VLOOKUP(AC31,GroupLabels!$E$2:$H$145,3,0) -> Denmark - Danish
A32: Denmark - Faroese | B32: 8 | C32: 6 | D32: 4 | E32: a | F32: 5 | G32: 5 | H32: 4 | I32: 5 | J32: 5 | AC32: fo-DK | AD32: =VLOOKUP(AC32,GroupLabels!$E$2:$H$145,3,0) -> Denmark - Faroese
A33: Dominican Republic - Spanish | B33: 8 | C33: 6 | D33: 4 | E33: 4 | F33: 5 | G33: 5 | H33: 4 | I33: 5 | J33: 5 | AC33: es-DO | AD33: =VLOOKUP(AC33,GroupLabels!$E$2:$H$145,3,0) -> Dominican Republic - Spanish
A34: Dushanbe (Tajikistan) - Russian | B34: 8 | C34: 6 | D34: 4 | E34: 4 | F34: a | G34: a | H34: 4 | I34: 5 | J34: 5 | AC34: ru-TJ | AD34: =VLOOKUP(AC34,GroupLabels!$E$2:$H$145,3,0) -> Dushanbe (Tajikistan) - Russian
A35: Dushanbe (Tajikistan) - Tajik | B35: 8 | C35: 6 | D35: 4 | E35: 4 | F35: a | G35: a | H35: 4 | I35: 5 | J35: 5 | AC35: tg-TJ | AD35: =VLOOKUP(AC35,GroupLabels!$E$2:$H$145,3,0) -> Dushanbe (Tajikistan) - Tajik
A36: Ecuador - Spanish | B36: 8 | C36: 6 | D36: 4 | E36: 4 | F36: 5 | G36: 5 | H36: 4 | I36: 5 | J36: 5 | AC36: es-EC | AD36: =VLOOKUP(AC36,GroupLabels!$E$2:$H$145,3,0) -> Ecuador - Spanish
A37: El Salvador - Spanish | B37: 8 | C37: 6 | D37: 4 | E37: 4 | F37: 5 | G37: 5 | H37: 4 | I37: 5 | J37: 5 | AC37: es-SV | AD37: =VLOOKUP(AC37,GroupLabels!$E$2:$H$145,3,0) -> El Salvador - Spanish
A38: Estonia - Estonian | B38: 8 | C38: 6 | D38: 4 | E38: 4 | F38: 5 | G38: 5 | H38: 4 | I38: 5 | J38: 5 | AC38: et-EE | AD38: =VLOOKUP(AC38,GroupLabels!$E$2:$H$145,3,0) -> Estonia - Estonian
A39: Estonia - Russian | B39: 8 | C39: 6 | D39: 4 | E39: 4 | F39: 5 | G39: 5 | H39: 4 | I39: 5 | J39: 5 | AC39: ru-EE | AD39: =VLOOKUP(AC39,GroupLabels!$E$2:$H$145,3,0) -> Estonia - Russian
A40: Finland - Finnish | B40: 8 | C40: 6 | D40: 4 | E40: 4 | F40: 5 | G40: 5 | H40: 4 | I40: 5 | J40: 5 | AC40: fi-FI | AD40: =VLOOKUP(AC40,GroupLabels!$E$2:$H$145,3,0) -> Finland - Finnish
A41: Finland - Swedish | B41: 8 | C41: 6 | D41: 4 | E41: 4 | F41: 5 | G41: 5 | H41: 4 | I41: 5 | J41: 5 | AC41: sv-FI | AD41: =VLOOKUP(AC41,GroupLabels!$E$2:$H$145,3,0) -> Finland - Swedish
A42: France - French | B42: 8 | C42: 6 | D42: 4 | E42: 4 | F42: 5 | G42: 5 | H42: 4 | I42: 5 | J42: 5 | AC42: fr-FR | AD42: =VLOOKUP(AC42,GroupLabels!$E$2:$H$145,3,0) -> France - French
A43: Georgia - Azerbaijani | B43: 8 | C43: 6 | D43: 4 | E43: 4 | F43: 5 | G43: 5 | H43: 4 | I43: 5 | J43: 5 | AC43: az-GE | AD43: =VLOOKUP(AC43,GroupLabels!$E$2:$H$145,3,0) -> Georgia - Azerbaijani
...

Sheet T22.A.14
A1: Table of Contents
A3: Table 22.A.14
A4: Countries/economies for which the scale scores were suppressed for the IRT scales in the Student Questionnaire
A6: Scale | B6: Country/economy
A7: BELONG | B7: Cambodia | P7: KHM
A8: BELONG | B8: Guatemala | P8: GTM
A9: BELONG | B9: Kurdistan Region (Iraq)* | P9: QKI
A10: BELONG | B10: Lebanon* | P10: LBN
A11: BELONG | B11: Rwanda | P11: RWA
A12: BELONG | B12: Zambia | P12: ZMB
A13: COLLENEFF | B13: Cambodia | P13: KHM
A14: CURIO | B14: Cambodia | P14: KHM
A15: ENVCAPCH | B15: Cambodia | P15: KHM
A16: ICTRES | B16: Australia | P16: AUS
A17: ICTRES | B17: Austria | P17: AUT
A18: ICTRES | B18: Belgium | P18: BEL
... A55: PERSEV | B55: Zambia | P55: ZMB

Sheet T22.A.15
A1: Table of Contents
A3: Table 22.A.15
A4: Groups that did not administer the IRT scales in the Student Questionnaire
A6: Scale | B6: Country/economy (language group)
A7: AIUSESCH | B7: Cambodia - Khmer
A8: AIUSESCH | B8: Dushanbe (Tajikistan) - Russian
A9: AIUSESCH | B9: Dushanbe (Tajikistan) - Tajik
A10: AIUSESCH | B10: Kurdistan Region (Iraq) - English*
A11: AIUSESCH | B11: Kurdistan Region (Iraq) - Bahdini*
A12: AIUSESCH | B12: Kurdistan Region (Iraq) - Sorani*
A13: AIUSESCH | B13: Mauritius - English
A14: AIUSESCH | B14: Rwanda - English
A15: AIUSESCH | B15: Zambia - English
A16: COGABIL | B16: Cambodia - Khmer
A17: COGABIL | B17: Dushanbe (Tajikistan) - Russian
... A94: TEACHSUP | B94: Zambia - English

Sheet T22.A.16
A1: Table of Contents
A3: Table 22.A.16
A4: Items in the HOMEPOS scale
A6: Group (International) | B6: Item | C6: Wording | D6: Response categories | E6: Alpha | F6: Beta | G6: Step_1 | H6: Step_2 | I6: Step_3 | J6: Step_4 | K6: Step_5
A7: International | B7: ST250Q01JA | C7: Which of the following are in your <home>? A room of your own | D7: 2 | E7: 0.61662 | F7: -2.33529
A8: International | B8: ST250Q02JA | C8: Which of the following are in your <home>? A computer (laptop, desktop, or tablet) that you can use for school work | D8: 2 | E8: 1.42854 | F8: -3.54503
A9: International | B9: ST250Q03JA | C9: Which of the following are in your <home>? Educational Software or Apps | D9: 2 | E9: 0.72987 | F9: -1.98903
A10: International | B10: ST250Q04JA | C10: Which of the following are in your <home>? Your own <cell phone> with Internet access (e.g. smartphone) | D10: 2 | E10: 0.83435 | F10: -4.3237
A11: International | B11: ST250Q05JA | C11: Which of the following are in your <home>? Internet access (e.g. Wi-fi) (excluding through smartphones) | D11: 2 | E11: 1.26 | F11: -4.49797
A12: International | B12: ST250Q08DA | C12: Which of the following are in your <home>? Electric lighting | D12: 2 | E12: 0.90124 | F12: -4.66661
A13: International | B13: ST250Q09DA | C13: Which of the following are in your <home>? < Plumbed water > for consumption | D13: 2 | E13: 0.95186 | F13: -4.07788
A14: International | B14: ST250Q10DA | C14: Which of the following are in your <home>? Off-street parking (e.g. garage, private parking spot) | D14: 2 | E14: 0.88109 | F14: -1.53295
A15: International | B15: ST250Q11DA | C15: Which of the following are in your <home>? A garbage-collection service | D15: 2 | E15: 0.63942 | F15: -2.16873
A16: International | B16: ST250Q12DA | C16: Which of the following are in your <home>? A stove or burner for cooking | D16: 2 | E16: 1.24013 | F16: -5.55603
A17: International | B17: ST250Q13DA | C17: Which of the following are in your <home>? A table to have meals | D17: 2 | E17: 0.80356 | F17: -3.9282
A18: International | B18: ST250Q14DA | C18: Which of the following are in your <home>? A vacuum cleaner | D18: 2 | E18: 0.86152 | F18: -3.98529
... A31: International | B31: ST250Q28DA | C31: Which of the following are in your <home>? A subscription to a newspaper | D31: 2 | E31: 0.84564 | F31: 0.86567
A32: International | B32: ST251Q01JA | C32: How many of these items are there at your <home>? Cars, vans, or trucks | D32: 4 | E32: 0.71526 | F32: -0.63216 | G32: -1.09878 | H32: 0.11112 | I32: 0.98766
A33: International | B33: ST251Q03JA | C33: How many of these items are there at your <home>? Rooms with a bath or shower | D33: 4 | E33: 0.83107 | F33: -0.9301 | G33: -2.32565 | H33: 0.62899 | I33: 1.69666
A34: International | B34: ST251Q04JA | C34: How many of these items are there at your <home>? Rooms with a <flush toilet> | D34: 4 | E34: 0.9029 | F34: -1.02441 | G34: -1.91242 | H34: 0.35634 | I34: 1.55608
A35: International | B35: ST251Q06JA | C35: How many of these items are there at your <home>? Musical instruments (e.g. guitar, piano, <country-specific example>) | D35: 4 | E35: 0.39101 | F35: 0.14969 | G35: 0.07922 | H35: 0.31663 | I35: -0.39585
A36: International | B36: ST251Q07JA | C36: How many of these items are there at your <home>? Works of art (e.g. paintings, sculptures, <country-specific example>) | D36: 2 | E36: 0.75217 | F36: -1.39969
A37: International | B37: ST254Q01JA | C37: How many of the following <digital devices> are in your <home>? Televisions | D37: 3 | E37: 0.86133 | F37: -2.12666 | G37: -2.10864 | H37: 2.10864
A38: International | B38: ST254Q02JA | C38: How many of the following <digital devices> are in your <home>? Desktop computers | D38: 4 | E38: 0.86985 | F38: 0.69505 | G38: -1.90503 | H38: 0.72772 | I38: 1.17731
A39: International | B39: ST254Q03JA | C39: How many of the following <digital devices> are in your <home>? Laptop computers or notebooks | D39: 4 | E39: 1.2382 | F39: -0.32453 | G39: -2.63813 | H39: 0.48166 | I39: 2.15647
A40: International | B40: ST254Q04JA | C40: How many of the following <digital devices> are in your <home>? Tablets (e.g. <iPad®>, <BlackBerry® PlayBook>) | D40: 3 | E40: 0.93861 | F40: -0.38601 | G40: -1.0389 | H40: 1.0389
A41: International | B41: ST254Q05JA | C41: How many of the following <digital devices> are in your <home>? E-book readers (e.g. <Kindle>, <Kobo>, <Bookeen>) | D41: 3 | E41: 0.47086 | F41: 1.12794 | G41: -0.23954 | H41: 0.23954
A42: International | B42: ST255Q01JA | C42: How many books are there in your <home>? | D42: 6 | E42: 0.32241 | F42: 0.1479 | G42: -0.2213 | H42: -0.71459 | I42: 0.39655 | J42: 0.15498 | K42: 0.38436
A43: Group | B43: Item | C43: Wording | D43: Response categories | E43: Alpha | F43: Beta | G43: Step_1 | H43: Step_2 | I43: Step_3 | J43: Step_4 | K43: Step_5
A44: Albania | B44: ST251Q08JA | C44: How many of these items are there at your <home>? <country-specific> | D44: 4 | E44: 2.12652 | F44: -1.68128 | G44: -2.77157 | H44: 0.58516 | I44: 2.18641 | P44: ALB | Q44: =VLOOKUP(P44,GroupLabels!$J:$K,2,FALSE) -> 0
A45: Albania | B45: ST251Q09JA | C45: How many of these items are there at your <home>? <country-specific> | D45: 4 | E45: 0.83421 | F45: -1.58823 | G45: -2.26303 | H45: 0.63911 | I45: 1.62392 | P45: ALB | Q45: =VLOOKUP(P45,GroupLabels!$J:$K,2,FALSE) -> 0
A46: Australia | B46: ST251Q08JA | C46: How many of these items are there at your <home>? <country-specific> | D46: 4 | E46: 0.60618 | F46: -0.59213 | G46: -1.12663 | H46: 0.95035 | I46: 0.17628 | P46: AUS | Q46: =VLOOKUP(P46,GroupLabels!$J:$K,2,FALSE) -> 1
A47: Australia | B47: ST251Q09JA | C47: How many of these items are there at your <home>? <country-specific> | D47: 4 | E47: 0.32689 | F47: 0.10886 | G47: 1.9467 | H47: -0.25178 | I47: -1.69492 | P47: AUS | Q47: =VLOOKUP(P47,GroupLabels!$J:$K,2,FALSE) -> 1
A48: Azerbaijan | B48: ST251Q08JA | C48: How many of these items are there at your <home>? <country-specific> | D48: 4 | E48: 0.439 | F48: -1.91918 | G48: -0.59581 | H48: 0.01752 | I48: 0.57829 | P48: AZE | Q48: =VLOOKUP(P48,GroupLabels!$J:$K,2,FALSE) -> 0
A49: B-S-J-Z (China)* | B49: ST251Q08JA | C49: How many of these items are there at your <home>? <country-specific> | D49: 4 | E49: 0.66264 | F49: -0.67275 | G49: -3.41048 | H49: 1.41353 | I49: 1.99695 | P49: QCI | Q49: =VLOOKUP(P49,GroupLabels!$J:$K,2,FALSE) -> 0
A50: B-S-J-Z (China)* | B50: ST251Q09JA | C50: How many of these items are there at your <home>? <country-specific> | D50: 4 | E50: 0.80846 | F50: -2.787 | G50: -0.85899 | H50: 0.16867 | I50: 0.69032 | P50: QCI | Q50: =VLOOKUP(P50,GroupLabels!$J:$K,2,FALSE) -> 0
A51: Belgium (Flemish Community) | B51: ST251Q08JA | C51: How many of these items are there at your <home>? <country-specific> | D51: 4 | E51: 0.4414 | F51: -0.00482 | G51: 0.75184 | H51: 0.20174 | I51: -0.95358 | P51: QBL | Q51: =VLOOKUP(P51,GroupLabels!$J:$K,2,FALSE) -> 1
A52: Belgium (French Community) | B52: ST251Q08JA | C52: How many of these items are there at your <home>? <country-specific> | D52: 4 | E52: 0.27269 | F52: -0.48059 | G52: 1.15958 | H52: 0.78049 | I52: -1.94007 | P52: QBR | Q52: =VLOOKUP(P52,GroupLabels!$J:$K,2,FALSE) -> 1
A53: Brunei Darussalam | B53: ST251Q08JA | C53: How many of these items are there at your <home>? <country-specific> | D53: 4 | E53: 0.2781 | F53: 0.37457 | G53: 1.07495 | H53: 0.15842 | I53: -1.23337 | P53: BRN | Q53: =VLOOKUP(P53,GroupLabels!$J:$K,2,FALSE) -> 0
A54: Brunei Darussalam | B54: ST251Q09JA | C54: How many of these items are there at your <home>? <country-specific> | D54: 4 | E54: 0.48745 | F54: 0.23153 | G54: 0.95784 | H54: 0.033 | I54: -0.99084 | P54: BRN | Q54: =VLOOKUP(P54,GroupLabels!$J:$K,2,FALSE) -> 0
...

Sheet T22.A.17
A1: Table of Contents
A3: Table 22.A.17
A4: Recoding of items in the HOMEPOS scale
A6: Item | B6: Wording | C6: Recoded
A7: ST250Q01JA | B7: Which of the following are in your <home>? A room of your own | C7: 1 (Yes) recoded as 1
C8: 2 (No) recoded as 0
A9: ST250Q02JA | B9: Which of the following are in your <home>? A computer (laptop, desktop, or tablet) that you can use for school work | C9: 1 (Yes) recoded as 1
C10: 2 (No) recoded as 0
A11: ST250Q03JA | B11: Which of the following are in your <home>? Educational Software or Apps | C11: 1 (Yes) recoded as 1
C12: 2 (No) recoded as 0
A13: ST250Q04JA | B13: Which of the following are in your <home>? Your own <cell phone> with Internet access (e.g. smartphone) | C13: 1 (Yes) recoded as 1
C14: 2 (No) recoded as 0
A15: ST250Q05JA | B15: Which of the following are in your <home>? Internet access (e.g. Wi-fi) (excluding through smartphones) | C15: 1 (Yes) recoded as 1
C16: 2 (No) recoded as 0
A17: ST250Q08DA | B17: Which of the following are in your <home>? Electric lighting | C17: 1 (Yes) recoded as 1
C18: 2 (No) recoded as 0
A19: ST250Q09DA | B19: Which of the following are in your <home>? < Plumbed water > for consumption | C19: 1 (Yes) recoded as 1
C20: 2 (No) recoded as 0
A21: ST250Q10DA | B21: Which of the following are in your <home>? Off-street parking (e.g. garage, private parking spot) | C21: 1 (Yes) recoded as 1
C22: 2 (No) recoded as 0
A23: ST250Q11DA | B23: Which of the following are in your <home>? A garbage-collection service | C23: 1 (Yes) recoded as 1
C24: 2 (No) recoded as 0
A25: ST250Q12DA | B25: Which of the following are in your <home>? A stove or burner for cooking | C25: 1 (Yes) recoded as 1
C26: 2 (No) recoded as 0
A27: ST250Q13DA | B27: Which of the following are in your <home>? A table to have meals | C27: 1 (Yes) recoded as 1
C28: 2 (No) recoded as 0
A29: ST250Q14DA | B29: Which of the following are in your <home>? A vacuum cleaner | C29: 1 (Yes) recoded as 1
C30: 2 (No) recoded as 0
A31: ST250Q15DA | B31: Which of the following are in your <home>? A refrigerator or freezer | C31: 1 (Yes) recoded as 1
C32: 2 (No) recoded as 0
A33: ST250Q16DA | B33: Which of the following are in your <home>? A sewer connection | C33: 1 (Yes) recoded as 1
C34: 2 (No) recoded as 0
